<mujoco model="left_arm_4_dof">
  <compiler angle="radian" meshdir="meshes/"/>

  <option timestep="0.001" gravity="0 0 0" integrator="implicitfast" iterations="50"/>

  <size njmax="500" nconmax="100"/>

  <visual>
    <global offwidth="1920" offheight="1080"/>
    <scale framelength="0.7" framewidth="0.02"/>
  </visual>

  <default>
    <joint limited="true"/>
    <geom contype="0" conaffinity="0"/>
    <default class="visual">
      <geom type="mesh" condim="1"/>
    </default>
    <default class="collision">
      <geom type="mesh" group="1"/>
    </default>
  </default>

  <asset>
    <texture type="skybox" name="texplane1" builtin="gradient" rgb1="0.4 0.5 0.6" rgb2="0 0 0" width="100" height="600"/>
    <texture type="2d" name="texplane" builtin="checker" rgb1="0.2 0.3 0.4" rgb2="0.1 0.15 0.2" width="100" height="100"/>
    <material name="MatPlane" texture="texplane" texuniform="true" reflectance="0.5"/>
    <mesh name="base_link" file="base_link.STL"/>
    <mesh name="R_hipY_Link" file="R_hipY_Link.STL"/>
    <mesh name="R_hipR_Link" file="R_hipR_Link.STL"/>
    <mesh name="R_hipP_Link" file="R_hipP_Link.STL"/>
    <mesh name="R_knee_Link" file="R_knee_Link.STL"/>
    <mesh name="R_ankleY_Link" file="R_ankleY_Link.STL"/>
    <mesh name="R_ankleR_Link" file="R_ankleR_Link.STL"/>
    <mesh name="R_ankleP_Link" file="R_ankleP_Link.STL"/>
    <mesh name="R_ankleP_Link_c" file="R_ankleP_Link.STL"/>
    <mesh name="R_sole_Link" file="R_sole_Link.STL"/>
    <mesh name="R_sole_Link_c" file="R_sole_Link.STL"/>
    <mesh name="L_hipY_Link" file="L_hipY_Link.STL"/>
    <mesh name="L_hipR_Link" file="L_hipR_Link.STL"/>
    <mesh name="L_hipP_Link" file="L_hipP_Link.STL"/>
    <mesh name="L_knee_Link" file="L_knee_Link.STL"/>
    <mesh name="L_ankleY_Link" file="L_ankleY_Link.STL"/>
    <mesh name="L_ankleR_Link" file="L_ankleR_Link.STL"/>
    <mesh name="L_ankleP_Link" file="L_ankleP_Link.STL"/>
    <mesh name="L_ankleP_Link_c" file="L_ankleP_Link.STL"/>
    <mesh name="L_sole_Link" file="L_sole_Link.STL"/>
    <mesh name="L_sole_Link_c" file="L_sole_Link.STL"/>
    <mesh name="torsoY_Link" file="torsoY_Link.STL"/>
    <mesh name="torsoR_Link" file="torsoR_Link.STL"/>
    <mesh name="torsoP_Link" file="torsoP_Link_l.STL"/>
    <mesh name="R_shoulderY_Link" file="R_shoulderY_Link.STL"/>
    <mesh name="R_shoulderR_Link" file="R_shoulderR_Link.STL"/>
    <mesh name="R_elbowY_Link" file="R_elbowY_Link.STL"/>
    <mesh name="R_elbowR_Link" file="R_elbowR_Link.STL"/>
    <mesh name="L_shoulderY_Link" file="L_shoulderY_Link.STL"/>
    <mesh name="L_shoulderR_Link" file="L_shoulderR_Link.STL"/>
    <mesh name="L_elbowY_Link" file="L_elbowY_Link.STL"/>
    <mesh name="L_elbowR_Link" file="L_elbowR_Link.STL"/>
    <mesh name="neckR_Link" file="neckR_Link.STL"/>
    <mesh name="neckP_Link" file="neckP_Link.STL"/>
    <mesh name="headR_Link" file="headR_Link.STL"/>
    <mesh name="headP_Link" file="headP_Link.STL"/>
    <mesh name="headY_Link" file="headY_Link.STL"/>
  </asset>

  <worldbody>
    <geom name="floor" size="500 500 0.125" type="plane" contype="1" conaffinity="1" group="2" friction="1 0.8 0.8" material="MatPlane" rgba="0.8 0.9 0.8 1"/>
    <light pos="0 0 1.3" dir="0 0 -1" directional="true" castshadow="false" cutoff="100" exponent="1" diffuse="1 1 1" specular="0.1 0.1 0.1"/>
    <body name="base_link" pos="0 0 0.95">
      <inertial pos="-0.00119987 0.00043033 -0.0376466" quat="0.720435 0.0262236 0.0220166 0.692677" mass="1.38" diaginertia="0.00305403 0.00234908 0.00110434"/>
      <geom class="visual" rgba="1.5 1.5 1.5 1" mesh="base_link"/>
      <body name="torsoY_Link" pos="-0.00482885 0 0.0660669" quat="0.972368 -0.000407209 0.233445 -0.00169615">
        <inertial pos="-0.00119987 0.00043033 -0.0376466" quat="0.720435 0.0262236 0.0220166 0.692677" mass="1.38" diaginertia="0.00305403 0.00234908 0.00110434"/>
        <geom class="visual" rgba="0.6 0.6 0.6 1" mesh="torsoY_Link"/>
        <body name="torsoR_Link" pos="0.00223949 0 0.057" quat="0.999998 0 0 0.00174434">
          <inertial pos="-0.0045593 1.65e-06 1.635e-05" quat="0.000402195 0.707107 0.000402195 0.707107" mass="2.13" diaginertia="0.00250818 0.00235874 0.00225394"/>
          <geom class="visual" rgba="0.3 0.3 0.3 1" mesh="torsoR_Link"/>
          <body name="torsoP_Link" quat="0.97237 0 -0.233444 0">
            <inertial pos="0 0.00060318 0.187298" mass="9.46" diaginertia="0.102012 0.0825985 0.0559009"/>
            <geom class="visual" rgba="1.5 1.5 1.5 1" mesh="torsoP_Link"/>
            <geom size="0.09 0.125" pos="0 0 0.17" type="cylinder" group="1" rgba="1.5 1.5 1.5 0"/>
            <site name="torsop_imu" pos="0 0 0" size="0.01"/>
            <site name="torso_imu" pos="0 0 0.26" size="0.01"/>
            <body name="L_shoulderY_Link" pos="0.00679205 0.130034 0.260803" quat="0.925548 -0.37734 0.0117904 0.0289197">
              <inertial pos="0.00138896 0.00748738 0.0246109" quat="0.690803 0.197341 0.46478 0.51752" mass="0.064" diaginertia="3.6238e-05 2.83656e-05 2.55964e-05"/>
              <joint name="arm_left_humeraly" pos="0 0 0" axis="0 0 -1" range="-1.2 2.3"/>
              <geom class="visual" rgba="0.6 0.6 0.6 1" mesh="L_shoulderY_Link"/>
              <body name="L_shoulderR_Link" pos="-0.00184029 0.011 0.038" quat="0.99562 -0.0934909 0 0">
                <inertial pos="-0.00168235 0.0303773 -0.00596837" quat="0.565363 0.397009 -0.426 0.584185" mass="0.77" diaginertia="0.00205003 0.00201329 0.000520217"/>
                <joint name="arm_left_humeralr" pos="0 0 0" axis="1 0 0" range="-0.15 1"/>
                <geom class="visual" rgba="1.5 1.5 1.5 1" mesh="L_shoulderR_Link"/>
                <geom size="0.035 0.0425" pos="0.002 0.05 -0.01" quat="0.540302 -0.841471 0 0" type="cylinder" group="1" rgba="1.5 1.5 1.5 0"/>
                <body name="L_elbowY_Link" pos="0.0009 0.109108 -0.0422899" quat="0.649131 0.397226 -0.338608 0.55334">
                  <inertial pos="-0.00070115 0.00079643 -0.0602248" quat="0.787773 0.00142783 -0.00189946 0.615961" mass="0.673" diaginertia="0.00125624 0.00118658 0.000254297"/>
                  <joint name="arm_left_wristr" pos="0 0 0" axis="0 0 1" range="0 1"/>
                  <geom class="visual" rgba="0.6 0.6 0.6 1" mesh="L_elbowY_Link"/>
                  <geom size="0.03 0.05" pos="0 0 -0.055" type="cylinder" group="1" rgba="0.6 0.6 0.6 0"/>
                  <body name="L_elbowR_Link" pos="-0.00155284 0.000385608 -0.1267" quat="0.992468 0.0163808 -0.00200346 -0.121384">
                    <inertial pos="0.0010561 0.00010278 -0.0528535" quat="0.681792 0.000900858 0.00104903 0.731545" mass="1.373" diaginertia="0.0100972 0.0100662 0.000581097"/>
                    <joint name="arm_left_wristr1" pos="0 0 0" axis="-1 0 0" range="0 2"/>
                    <geom class="visual" rgba="1.5 1.5 1.5 1" mesh="L_elbowR_Link"/>
                    <geom size="0.03 0.135" pos="0 0 -0.155" type="cylinder" group="1" rgba="1.5 1.5 1.5 0"/>
                    <body name="eef" pos="0 0 -0.27">
                      <geom size="0.03" rgba="1 0 0 0.1"/>
                    </body>
                  </body>
                </body>
              </body>
            </body>
          </body>
        </body>
      </body>
    </body>
    <body name="test" pos="0.35 0 1.15">
      <geom size="0.01" rgba="1 0 1 0.9"/>
    </body>
    <body name="visual_test" pos="0.3 0 1.1">
      <geom size="0.01" rgba="0 0 1 0.9"/>
    </body>
  </worldbody>

  <actuator>
    <general name="act1" joint="arm_left_humeraly" ctrlrange="-1.2 2.3" biastype="affine" gainprm="1000" biasprm="0 -1000 -100"/>
    <general name="act2" joint="arm_left_humeralr" ctrlrange="-0.15 1" biastype="affine" gainprm="3000" biasprm="0 -3000 -300"/>
    <general name="act3" joint="arm_left_wristr" ctrlrange="0 1" biastype="affine" gainprm="3000" biasprm="0 -3000 -300"/>
    <general name="act4" joint="arm_left_wristr1" ctrlrange="0 2" biastype="affine" gainprm="2000" biasprm="0 -2000 -200"/>
  </actuator>
</mujoco>
