<?xml version="1.0"?>
<robot name="robot">
  <link name="base_link">
    <visual>
      <geometry>
        <box size="0.1 0.1 0.1"/>
      </geometry>
    </visual>
  </link>
  <joint name="joint_1" type="revolute">
    <parent link="base_link"/>
    <child link="link_1"/>
    <axis xyz="0 0 1"/>
    <origin rpy="0 0 0" xyz="0 0 0.1"/>
  </joint>
  <link name="link_1">
    <visual>
      <geometry>
        <cylinder radius="0.02" length="0.5"/>
      </geometry>
    </visual>
  </link>
  <joint name="joint_2" type="revolute">
    <parent link="link_1"/>
    <child link="link_2"/>
    <axis xyz="0 1 0"/>
    <origin rpy="0 0 0" xyz="0 0.5 0"/>
  </joint>
  <link name="link_2">
    <visual>
      <geometry>
        <cylinder radius="0.02" length="0.5"/>
      </geometry>
    </visual>
  </link>
  <joint name="joint_3" type="revolute">
    <parent link="link_2"/>
    <child link="link_3"/>
    <axis xyz="0 0 1"/>
    <origin rpy="0 0 0" xyz="0 0.5 0"/>
  </joint>
  <link name="link_3">
    <visual>
      <geometry>
        <cylinder radius="0.02" length="0.5"/>
      </geometry>
    </visual>
  </link>
  <joint name="joint_4" type="revolute">
    <parent link="link_3"/>
    <child link="end_effector"/>
    <axis xyz="0 1 0"/>
    <origin rpy="0 0 0" xyz="0 0.5 0"/>
  </joint>
  <link name="end_effector">
    <visual>
      <geometry>
        <sphere radius="0.05"/>
      </geometry>
    </visual>
  </link>
</robot>